Workbook
Name hoje: TODAY()
Name hoje: TODAY()
Name hoje: TODAY()
Name início_da_tarefa: Gantt!$E1
Name início_da_tarefa: Infoestrutura!$E1
Name início_da_tarefa: Telessaúde!$E1
Name início_da_tarefa: #REF!
Name Início_do_projeto: Gantt!$E$3
Name Início_do_projeto: Telessaúde!$E$3
Name Início_do_projeto: Infoestrutura!$E$3
Name progresso_da_tarefa: Gantt!$D1
Name progresso_da_tarefa: Infoestrutura!$D1
Name progresso_da_tarefa: Telessaúde!$D1
Name progresso_da_tarefa: #REF!
Name Semana_de_exibição: Gantt!$E$4
Name Semana_de_exibição: Telessaúde!$E$4
Name Semana_de_exibição: Infoestrutura!$E$4
Name término_da_tarefa: Gantt!$F1
Name término_da_tarefa: Infoestrutura!$F1
Name término_da_tarefa: Telessaúde!$F1
Name término_da_tarefa: #REF!

Sheet OKR 
C3: Painel de Acompanhamento
C6: MICRORREGIÃO BELO HORIZONTE/NOVA LIMA/SANTA LUZIA
C8: Eixo: 2 - Formação e Desenvolvimento
C10: OBJETIVO: | D10: Implementar um GT de Saúde Digital microrregional para formação dos profissionais de saúde
C12: Descrição do objetivo
C14: Fortalecer a capacidade institucional dos municípios para planejar, implementar e sustentar ações de saúde digital, por meio de uma estrutura organizada de governança e de processos contínuos de formação, alinhados às diretrizes estaduais e às necessidades do território.
C16: Resultados esperados
C18: - Estrutura microrregional organizada para coordenação das ações de formação em saúde digital; - Profissionais municipais mais qualificados para atuar nos processos e sistemas de saúde digital; - Maior alinhamento entre as formações realizadas e as prioridades regionais; - Uso mais consistente das ferramentas e informações digitais no apoio à gestão e à assistência. - Redução no retrabalho por uso errado de sistemas e produção de informações.
C20: AT1 | D20: Criar a Governança do GT de Saúde Digital para formação | F20: Descrição: Constituir uma instância microrregional de articulação e coordenação das ações de formação em saúde digital, reunindo representantes das áreas técnicas, de gestão, TIC e educação permanente, com a finalidade de planejar, organizar, acompanhar e alinhar as formações às necessidades regionais e às diretrizes estaduais.
D22: AÇÕES CHAVE PARA CONCLUIR A ATIVIDADE | E22: Áreas envolvidas | F22: Status | G22: Data de Início | H22: Término Planejado | I22: Tendência de Término
D23: Definir escopo do grupo (responsabilidades, atribuições, frequência das reuniões, governança) | E23: SMS, NSDIGI, Regional, Cosems | G23: 46055 | H23: 46080
D24: Indicar representantes | E24: Gestores Municipais | G24: 46055 | H24: 46080
D25: Formalizar equipe Intersetorial na CIB microrregional | E25: Gestores Municipais | G25: 46083 | H25: 46112
D26: Capacitar equipe intersetorial | E26: NSDIGI | G26: 46083 | H26: 46142
C37: AT2 | D37: Implementar gestão regional de formações | F37: Descrição: Estruturar um modelo regional de gestão das formações em saúde digital, contemplando diagnóstico de demandas, definição de públicos-alvo, organização de trilhas de aprendizagem, planejamento de calendário, acompanhamento da participação e sistematização de informações para apoio à tomada de decisão.
D39: AÇÕES CHAVE PARA CONCLUIR A ATIVIDADE | E39: Áreas envolvidas | F39: Status | G39: Data de Início | H39: Término Planejado | I39: Tendência de Término
D40: Avaliar dados do Valorizagtes-sus | E40: Grupo de Trabalho | G40: 46055 | H40: 46142
D41: Avaliar diagnóstico de demanda por formações do Valoriza SUS | E41: Grupo de Trabalho | G41: 46055 | H41: 46142
D42: Avaliar a inclusão da temática de Saúde Digital no Valoriza SUS | E42: Grupo de Trabalho | G42: 46055 | H42: 46142
D43: Criar rotina regional de formação | E43: Grupo de Trabalho | G43: 46054 | H43: 46142
D44: Identificar necessidades locais e planejar ações. | E44: Grupo de Trabalho | G44: 46113 | H44: 46173
D45: Desenvolver protocolos e indicadores. | E45: Grupo de Trabalho | G45: 46113 | H45: 46173
D46: Elaborar modelo avaliação das formações | E46: Grupo de Trabalho | G46: 46113 | H46: 46173
D47: Definir portfólio de cursos (fixos e sazionais) | E47: Grupo de Trabalho | G47: 46113 | H47: 46203
D48: Solicitar treinamentos conforme necessidades. | E48: Grupo de Trabalho | G48: 46113 | H48: 46387
D49: Apresentar resultados das qualificações - CIB Micro | E49: Grupo de Trabalho | G49: 46327 | H49: 46356
C56: AT3 | D56: Realizar 1º ciclo completo de formações | F56: Descrição: Executar o primeiro ciclo estruturado de formações em saúde digital na microrregião, mobilizando os profissionais indicados, realizando os treinamentos planejados, sistematizando informações sobre participação e apoiando a análise dos resultados obtidos para orientar os ciclos seguintes de qualificação.
D58: AÇÕES CHAVE PARA CONCLUIR A ATIVIDADE | E58: Áreas envolvidas | F58: Status | G58: Data de Início | H58: Término Planejado | I58: Tendência de Término
D59: Realizar campanha de sensibilização e mobilização para formações | E59: Grupo de Trabalho; Regional; Gestores Municipais | G59: 46113 | H59: 46173
D60: Realizar formações priorizadas | E60: Grupo de Trabalho, Regional, Gestores Municipais, NSDIGI, Grupo de Telessaúde e Gestão de Dados | G60: 46143 | H60: 46234
D61: Aplicar avaliação | E61: Grupo de Trabalho | G61: 46235 | H61: 46265
D62: Definir uma rede de apoio pós-treinamentos. | E62: Grupo de Trabalho | G62: 46235 | H62: 46325
C73: Eixo: 4 - Telessaúde
C75: OBJETIVO: | D75: Utilizar Telessaúde para otimizar e ampliar o acesso aos serviços do SUS
C77: Descrição do objetivo
C79: Ampliar e qualificar o acesso aos serviços de saúde por meio da utilização estruturada da Telessaúde, promovendo sua incorporação gradual aos processos assistenciais e de apoio à gestão, de forma articulada entre os municípios e alinhada às diretrizes estaduais.
C81: Resultados esperados
C83: - Governança microrregional organizada para condução das ações de Telessaúde; - Maior conhecimento sobre a situação de uso da Telessaúde no território; - Ampliação progressiva do uso da teleconsultoria; - Profissionais mais preparados para utilizar a Telessaúde de forma adequada e segura.
C85: AT1 | D85: Organizar a governança e a estrutura institucional da Telessaúde | F85: Descrição: Estruturar a governança microrregional da Telessaúde, definindo instâncias de articulação, responsabilidades, diretrizes de funcionamento, fluxos de utilização, parâmetros mínimos e indicadores, de modo a apoiar a organização, o acompanhamento e o aprimoramento contínuo das ações no território.
D87: AÇÕES CHAVE PARA CONCLUIR A ATIVIDADE | E87: Áreas envolvidas | F87: Status | G87: Data de Início | H87: Término Planejado | I87: Tendência de Término
...

Sheet Base Plano
A1: Eixo | B1: Macroatividade | C1: Ação | D1: Área Responsável | E1: Início | F1: Fim | G1: Duração (dias) | H1: Eixo 2 | I1: Eixo 4 | J1: Eixo 6 | K1: descrição atividade | L1: micro | M1: Objetivo
A2: Eixo: 2 - Formação e Desenvolvimento | B2: Implementar gestão regional de formações | C2: Criar rotina regional de formação | D2: Grupo de Trabalho | E2: 46054 | F2: 46142 | G2: =F2-E2 -> 88 | H2: {=IF($A2="Eixo: 2 - Formação e Desenvolvimento",$G2,_xludf.NA())} -> 88 | I2: {=IF($A2="Eixo: 4 - Telessaúde",$G2,_xludf.NA())} -> #NAME? | J2: {=IF($A2="Eixo: 6 - Monitoramento, avaliação e disseminação de informações estratégicas",$G2,_xludf.NA())} -> #NAME?
A3: Eixo: 2 - Formação e Desenvolvimento | B3: Criar a Governança do GT de Saúde Digital para formação | C3: Definir escopo do grupo (responsabilidades, atribuições, frequência das reuniões, governança) | D3: SMS, NSDIGI, Regional, Cosems | E3: 46055 | F3: 46080 | G3: =F3-E3 -> 25 | H3: {=IF($A3="Eixo: 2 - Formação e Desenvolvimento",$G3,_xludf.NA())} -> 25 | I3: {=IF($A3="Eixo: 4 - Telessaúde",$G3,_xludf.NA())} -> #NAME? | J3: {=IF($A3="Eixo: 6 - Monitoramento, avaliação e disseminação de informações estratégicas",$G3,_xludf.NA())} -> #NAME?
A4: Eixo: 2 - Formação e Desenvolvimento | B4: Criar a Governança do GT de Saúde Digital para formação | C4: Indicar representantes | D4: Gestores Municipais | E4: 46055 | F4: 46080 | G4: =F4-E4 -> 25 | H4: {=IF($A4="Eixo: 2 - Formação e Desenvolvimento",$G4,_xludf.NA())} -> 25 | I4: {=IF($A4="Eixo: 4 - Telessaúde",$G4,_xludf.NA())} -> #NAME? | J4: {=IF($A4="Eixo: 6 - Monitoramento, avaliação e disseminação de informações estratégicas",$G4,_xludf.NA())} -> #NAME?
A5: Eixo: 2 - Formação e Desenvolvimento | B5: Implementar gestão regional de formações | C5: Avaliar dados do Valorizagtes-sus | D5: Grupo de Trabalho | E5: 46055 | F5: 46142 | G5: =F5-E5 -> 87 | H5: {=IF($A5="Eixo: 2 - Formação e Desenvolvimento",$G5,_xludf.NA())} -> 87 | I5: {=IF($A5="Eixo: 4 - Telessaúde",$G5,_xludf.NA())} -> #NAME? | J5: {=IF($A5="Eixo: 6 - Monitoramento, avaliação e disseminação de informações estratégicas",$G5,_xludf.NA())} -> #NAME?
A6: Eixo: 2 - Formação e Desenvolvimento | B6: Implementar gestão regional de formações | C6: Avaliar diagnóstico de demanda por formações do Valoriza SUS | D6: Grupo de Trabalho | E6: 46055 | F6: 46142 | G6: =F6-E6 -> 87 | H6: {=IF($A6="Eixo: 2 - Formação e Desenvolvimento",$G6,_xludf.NA())} -> 87 | I6: {=IF($A6="Eixo: 4 - Telessaúde",$G6,_xludf.NA())} -> #NAME? | J6: {=IF($A6="Eixo: 6 - Monitoramento, avaliação e disseminação de informações estratégicas",$G6,_xludf.NA())} -> #NAME?
A7: Eixo: 2 - Formação e Desenvolvimento | B7: Implementar gestão regional de formações | C7: Avaliar a inclusão da temática de Saúde Digital no Valoriza SUS | D7: Grupo de Trabalho | E7: 46055 | F7: 46142 | G7: =F7-E7 -> 87 | H7: {=IF($A7="Eixo: 2 - Formação e Desenvolvimento",$G7,_xludf.NA())} -> 87 | I7: {=IF($A7="Eixo: 4 - Telessaúde",$G7,_xludf.NA())} -> #NAME? | J7: {=IF($A7="Eixo: 6 - Monitoramento, avaliação e disseminação de informações estratégicas",$G7,_xludf.NA())} -> #NAME?
A8: Eixo: 4 - Telessaúde | B8: ='OKR '!D122 -> Consolidar o uso da telessaúde na microrregião | C8: ='OKR '!D125 -> Definir agendas seguras para realização das teleconsultorias | D8: ='OKR '!E125 -> Área Técnica das SMS / Gestores com tomada de decisão | E8: ='OKR '!G125 -> 46055 | F8: ='OKR '!H125 -> 46112 | G8: =F8-E8 -> 57 | H8: {=IF($A8="Eixo: 2 - Formação e Desenvolvimento",$G8,_xludf.NA())} -> #NAME? | I8: {=IF($A8="Eixo: 4 - Telessaúde",$G8,_xludf.NA())} -> 57 | J8: {=IF($A8="Eixo: 6 - Monitoramento, avaliação e disseminação de informações estratégicas",$G8,_xludf.NA())} -> #NAME?
A9: Eixo: 4 - Telessaúde | B9: Consolidar o uso da telessaúde na microrregião | C9: ='OKR '!D126 -> Criar repositório permanente de casos e estudos | D9: ='OKR '!E126 -> Grupo de Estudo | E9: ='OKR '!G126 -> 46055 | F9: ='OKR '!H126 -> 46112 | G9: =F9-E9 -> 57 | H9: {=IF($A9="Eixo: 2 - Formação e Desenvolvimento",$G9,_xludf.NA())} -> #NAME? | I9: {=IF($A9="Eixo: 4 - Telessaúde",$G9,_xludf.NA())} -> 57 | J9: {=IF($A9="Eixo: 6 - Monitoramento, avaliação e disseminação de informações estratégicas",$G9,_xludf.NA())} -> #NAME?
A10: Eixo: 4 - Telessaúde | B10: Consolidar o uso da telessaúde na microrregião | C10: ='OKR '!D127 -> Estruturar grupo de estudo sobre telessaúde (implementação, operação, inovação... ) | D10: ='OKR '!E127 -> Equipe Microrregional | E10: ='OKR '!G127 -> 46055 | F10: ='OKR '!H127 -> 46112 | G10: =F10-E10 -> 57 | H10: {=IF($A10="Eixo: 2 - Formação e Desenvolvimento",$G10,_xludf.NA())} -> #NAME? | I10: {=IF($A10="Eixo: 4 - Telessaúde",$G10,_xludf.NA())} -> 57 | J10: {=IF($A10="Eixo: 6 - Monitoramento, avaliação e disseminação de informações estratégicas",$G10,_xludf.NA())} -> #NAME?
A11: ='OKR '!C73 -> Eixo: 4 - Telessaúde | B11: ='OKR '!D85 -> Organizar a governança e a estrutura institucional da Telessaúde | C11: ='OKR '!D88 -> Definir representantes municipais para atuar na condução conjunta da Telessaúde na microrregião | D11: ='OKR '!E88 -> Gestores Municipais | E11: ='OKR '!G88 -> 46055 | F11: ='OKR '!H88 -> 46080 | G11: =F11-E11 -> 25 | H11: {=IF($A11="Eixo: 2 - Formação e Desenvolvimento",$G11,_xludf.NA())} -> #NAME? | I11: {=IF($A11="Eixo: 4 - Telessaúde",$G11,_xludf.NA())} -> 25 | J11: {=IF($A11="Eixo: 6 - Monitoramento, avaliação e disseminação de informações estratégicas",$G11,_xludf.NA())} -> #NAME?
A12: Eixo: 4 - Telessaúde | B12: Organizar a governança e a estrutura institucional da Telessaúde | C12: ='OKR '!D89 -> Instituir instância de governança microrregional (escopo de atuação, atribuições, regularidade dos encontros etc) | D12: ='OKR '!E89 -> SMS ; Equipe da Telessaúde ; NSDIGI ; Cosems | E12: ='OKR '!G89 -> 46055 | F12: ='OKR '!H89 -> 46112 | G12: =F12-E12 -> 57 | H12: {=IF($A12="Eixo: 2 - Formação e Desenvolvimento",$G12,_xludf.NA())} -> #NAME? | I12: {=IF($A12="Eixo: 4 - Telessaúde",$G12,_xludf.NA())} -> 57 | J12: {=IF($A12="Eixo: 6 - Monitoramento, avaliação e disseminação de informações estratégicas",$G12,_xludf.NA())} -> #NAME?
A13: Eixo: 6 - Monitoramento, avaliação e disseminação de informações estratégicas | B13: ='OKR '!D171 -> Definir padrões mínimos e governança de dados | C13: ='OKR '!D174 -> Instituir governança local de dados | D13: ='OKR '!E174 -> Grupo de trabalho, NSDIGI, Gestores Municipais | E13: ='OKR '!G174 -> 46055 | F13: ='OKR '!H174 -> 46112 | G13: =F13-E13 -> 57 | H13: {=IF($A13="Eixo: 2 - Formação e Desenvolvimento",$G13,_xludf.NA())} -> #NAME? | I13: {=IF($A13="Eixo: 4 - Telessaúde",$G13,_xludf.NA())} -> #NAME? | J13: {=IF($A13="Eixo: 6 - Monitoramento, avaliação e disseminação de informações estratégicas",$G13,_xludf.NA())} -> 57
A14: Eixo: 6 - Monitoramento, avaliação e disseminação de informações estratégicas | B14: Definir padrões mínimos e governança de dados | C14: ='OKR '!D175 -> Definir fluxos de decisão e escalonamento | D14: ='OKR '!E175 -> Comitê de Governança | E14: ='OKR '!G175 -> 46055 | F14: ='OKR '!H175 -> 46112 | G14: =F14-E14 -> 57 | H14: {=IF($A14="Eixo: 2 - Formação e Desenvolvimento",$G14,_xludf.NA())} -> #NAME? | I14: {=IF($A14="Eixo: 4 - Telessaúde",$G14,_xludf.NA())} -> #NAME? | J14: {=IF($A14="Eixo: 6 - Monitoramento, avaliação e disseminação de informações estratégicas",$G14,_xludf.NA())} -> 57
A15: Eixo: 6 - Monitoramento, avaliação e disseminação de informações estratégicas | B15: Definir padrões mínimos e governança de dados | C15: ='OKR '!D176 -> Estabelecer fluxo de comunicação com a regional e o estado | D15: ='OKR '!E176 -> Comitê de Governança | E15: ='OKR '!G176 -> 46055 | F15: ='OKR '!H176 -> 46112 | G15: =F15-E15 -> 57 | H15: {=IF($A15="Eixo: 2 - Formação e Desenvolvimento",$G15,_xludf.NA())} -> #NAME? | I15: {=IF($A15="Eixo: 4 - Telessaúde",$G15,_xludf.NA())} -> #NAME? | J15: {=IF($A15="Eixo: 6 - Monitoramento, avaliação e disseminação de informações estratégicas",$G15,_xludf.NA())} -> 57
A16: Eixo: 6 - Monitoramento, avaliação e disseminação de informações estratégicas | B16: Definir padrões mínimos e governança de dados | C16: ='OKR '!D177 -> Definir instância mínima de decisão (ponto focal ou comitê) | D16: ='OKR '!E177 -> Gestores Municipais | E16: ='OKR '!G177 -> 46055 | F16: ='OKR '!H177 -> 46112 | G16: =F16-E16 -> 57 | H16: {=IF($A16="Eixo: 2 - Formação e Desenvolvimento",$G16,_xludf.NA())} -> #NAME? | I16: {=IF($A16="Eixo: 4 - Telessaúde",$G16,_xludf.NA())} -> #NAME? | J16: {=IF($A16="Eixo: 6 - Monitoramento, avaliação e disseminação de informações estratégicas",$G16,_xludf.NA())} -> 57
A17: Eixo: 6 - Monitoramento, avaliação e disseminação de informações estratégicas | B17: Definir padrões mínimos e governança de dados | C17: ='OKR '!D178 -> Designar responsáveis formais pela governança dos dados | D17: ='OKR '!E178 -> Gestores Municipais | E17: ='OKR '!G178 -> 46055 | F17: ='OKR '!H178 -> 46112 | G17: =F17-E17 -> 57 | H17: {=IF($A17="Eixo: 2 - Formação e Desenvolvimento",$G17,_xludf.NA())} -> #NAME? | I17: {=IF($A17="Eixo: 4 - Telessaúde",$G17,_xludf.NA())} -> #NAME? | J17: {=IF($A17="Eixo: 6 - Monitoramento, avaliação e disseminação de informações estratégicas",$G17,_xludf.NA())} -> 57
A18: Eixo: 6 - Monitoramento, avaliação e disseminação de informações estratégicas | B18: Definir padrões mínimos e governança de dados | C18: ='OKR '!D179 -> Definir regras de acesso e segurança da informação | D18: ='OKR '!E179 -> Grupo de trabalho | E18: ='OKR '!G179 -> 46055 | F18: ='OKR '!H179 -> 46265 | G18: =F18-E18 -> 210 | H18: {=IF($A18="Eixo: 2 - Formação e Desenvolvimento",$G18,_xludf.NA())} -> #NAME? | I18: {=IF($A18="Eixo: 4 - Telessaúde",$G18,_xludf.NA())} -> #NAME? | J18: {=IF($A18="Eixo: 6 - Monitoramento, avaliação e disseminação de informações estratégicas",$G18,_xludf.NA())} -> 210
A19: Eixo: 6 - Monitoramento, avaliação e disseminação de informações estratégicas | B19: Definir padrões mínimos e governança de dados | C19: ='OKR '!D180 -> Alinhar regras à LGPD e às diretrizes estaduais | D19: ='OKR '!E180 -> Grupo de trabalho | E19: ='OKR '!G180 -> 46055 | F19: ='OKR '!H180 -> 46265 | G19: =F19-E19 -> 210 | H19: {=IF($A19="Eixo: 2 - Formação e Desenvolvimento",$G19,_xludf.NA())} -> #NAME? | I19: {=IF($A19="Eixo: 4 - Telessaúde",$G19,_xludf.NA())} -> #NAME? | J19: {=IF($A19="Eixo: 6 - Monitoramento, avaliação e disseminação de informações estratégicas",$G19,_xludf.NA())} -> 210
A20: Eixo: 6 - Monitoramento, avaliação e disseminação de informações estratégicas | B20: Definir padrões mínimos e governança de dados | C20: ='OKR '!D181 -> Definir escopo claro do que será integrado em cada fase | D20: ='OKR '!E181 -> Grupo de trabalho | E20: ='OKR '!G181 -> 46055 | F20: ='OKR '!H181 -> 46265 | G20: =F20-E20 -> 210 | H20: {=IF($A20="Eixo: 2 - Formação e Desenvolvimento",$G20,_xludf.NA())} -> #NAME? | I20: {=IF($A20="Eixo: 4 - Telessaúde",$G20,_xludf.NA())} -> #NAME? | J20: {=IF($A20="Eixo: 6 - Monitoramento, avaliação e disseminação de informações estratégicas",$G20,_xludf.NA())} -> 210
A21: Eixo: 6 - Monitoramento, avaliação e disseminação de informações estratégicas | B21: Definir padrões mínimos e governança de dados | C21: ='OKR '!D182 -> Priorizar padrões conforme sistemas críticos mapeados | D21: ='OKR '!E182 -> Grupo de trabalho | E21: ='OKR '!G182 -> 46055 | F21: ='OKR '!H182 -> 46265 | G21: =F21-E21 -> 210 | H21: {=IF($A21="Eixo: 2 - Formação e Desenvolvimento",$G21,_xludf.NA())} -> #NAME? | I21: {=IF($A21="Eixo: 4 - Telessaúde",$G21,_xludf.NA())} -> #NAME? | J21: {=IF($A21="Eixo: 6 - Monitoramento, avaliação e disseminação de informações estratégicas",$G21,_xludf.NA())} -> 210
A22: Eixo: 6 - Monitoramento, avaliação e disseminação de informações estratégicas | B22: Definir padrões mínimos e governança de dados | C22: ='OKR '!D183 -> Priorizar padrões compatíveis com sistemas já existentes | D22: ='OKR '!E183 -> Grupo de trabalho | E22: ='OKR '!G183 -> 46055 | F22: ='OKR '!H183 -> 46265 | G22: =F22-E22 -> 210 | H22: {=IF($A22="Eixo: 2 - Formação e Desenvolvimento",$G22,_xludf.NA())} -> #NAME? | I22: {=IF($A22="Eixo: 4 - Telessaúde",$G22,_xludf.NA())} -> #NAME? | J22: {=IF($A22="Eixo: 6 - Monitoramento, avaliação e disseminação de informações estratégicas",$G22,_xludf.NA())} -> 210
A23: Eixo: 6 - Monitoramento, avaliação e disseminação de informações estratégicas | B23: Definir padrões mínimos e governança de dados | C23: ='OKR '!D184 -> Estabelecer padrões mínimos de troca de dados | D23: ='OKR '!E184 -> Grupo de trabalho | E23: ='OKR '!G184 -> 46055 | F23: ='OKR '!H184 -> 46265 | G23: =F23-E23 -> 210 | H23: {=IF($A23="Eixo: 2 - Formação e Desenvolvimento",$G23,_xludf.NA())} -> #NAME? | I23: {=IF($A23="Eixo: 4 - Telessaúde",$G23,_xludf.NA())} -> #NAME? | J23: {=IF($A23="Eixo: 6 - Monitoramento, avaliação e disseminação de informações estratégicas",$G23,_xludf.NA())} -> 210
A24: Eixo: 6 - Monitoramento, avaliação e disseminação de informações estratégicas | B24: Definir padrões mínimos e governança de dados | C24: ='OKR '!D185 -> Definir padrões básicos de interoperabilidade conforme orientação estadual | D24: ='OKR '!E185 -> Grupo de trabalho, NSDIGI | E24: ='OKR '!G185 -> 46055 | F24: ='OKR '!H185 -> 46265 | G24: =F24-E24 -> 210 | H24: {=IF($A24="Eixo: 2 - Formação e Desenvolvimento",$G24,_xludf.NA())} -> #NAME? | I24: {=IF($A24="Eixo: 4 - Telessaúde",$G24,_xludf.NA())} -> #NAME? | J24: {=IF($A24="Eixo: 6 - Monitoramento, avaliação e disseminação de informações estratégicas",$G24,_xludf.NA())} -> 210
A25: ='OKR '!C140 -> Eixo: 6 - Monitoramento, avaliação e disseminação de informações estratégicas | B25: ='OKR '!D152 -> Diagnosticar e mapear os sistemas de informação | C25: ='OKR '!D155 -> Nomear grupo de trabalho da micro | D25: ='OKR '!E155 -> Gestores municipais | E25: ='OKR '!G155 -> 46055 | F25: ='OKR '!H155 -> 46080 | G25: =F25-E25 -> 25 | H25: {=IF($A25="Eixo: 2 - Formação e Desenvolvimento",$G25,_xludf.NA())} -> #NAME? | I25: {=IF($A25="Eixo: 4 - Telessaúde",$G25,_xludf.NA())} -> #NAME? | J25: {=IF($A25="Eixo: 6 - Monitoramento, avaliação e disseminação de informações estratégicas",$G25,_xludf.NA())} -> 25
A26: Eixo: 6 - Monitoramento, avaliação e disseminação de informações estratégicas | B26: Diagnosticar e mapear os sistemas de informação | C26: ='OKR '!D156 -> Mapear os sistemas de informação em uso no município (ex: sistemas assistenciais, administrativos, regulatórios e de vigilância) | D26: ='OKR '!E156 -> Ponto de Referência municipal em Saúde Digital, Grupo de trabalho, NSDIGI, Regional e Cosems | E26: ='OKR '!G156 -> 46055 | F26: ='OKR '!H156 -> 46203 | G26: =F26-E26 -> 148 | H26: {=IF($A26="Eixo: 2 - Formação e Desenvolvimento",$G26,_xludf.NA())} -> #NAME? | I26: {=IF($A26="Eixo: 4 - Telessaúde",$G26,_xludf.NA())} -> #NAME? | J26: {=IF($A26="Eixo: 6 - Monitoramento, avaliação e disseminação de informações estratégicas",$G26,_xludf.NA())} -> 148
A27: Eixo: 6 - Monitoramento, avaliação e disseminação de informações estratégicas | B27: Diagnosticar e mapear os sistemas de informação | C27: ='OKR '!D157 -> Classificar os sistemas por criticidade e função | D27: ='OKR '!E157 -> Grupo de trabalho | E27: ='OKR '!G157 -> 46055 | F27: ='OKR '!H157 -> 46203 | G27: =F27-E27 -> 148 | H27: {=IF($A27="Eixo: 2 - Formação e Desenvolvimento",$G27,_xludf.NA())} -> #NAME? | I27: {=IF($A27="Eixo: 4 - Telessaúde",$G27,_xludf.NA())} -> #NAME? | J27: {=IF($A27="Eixo: 6 - Monitoramento, avaliação e disseminação de informações estratégicas",$G27,_xludf.NA())} -> 148
A28: Eixo: 6 - Monitoramento, avaliação e disseminação de informações estratégicas | B28: Diagnosticar e mapear os sistemas de informação | C28: ='OKR '!D158 -> Identificar sistemas essenciais para continuidade do cuidado | D28: ='OKR '!E158 -> Grupo de trabalho | E28: ='OKR '!G158 -> 46055 | F28: ='OKR '!H158 -> 46203 | G28: =F28-E28 -> 148 | H28: {=IF($A28="Eixo: 2 - Formação e Desenvolvimento",$G28,_xludf.NA())} -> #NAME? | I28: {=IF($A28="Eixo: 4 - Telessaúde",$G28,_xludf.NA())} -> #NAME? | J28: {=IF($A28="Eixo: 6 - Monitoramento, avaliação e disseminação de informações estratégicas",$G28,_xludf.NA())} -> 148
A29: Eixo: 6 - Monitoramento, avaliação e disseminação de informações estratégicas | B29: Diagnosticar e mapear os sistemas de informação | C29: ='OKR '!D159 -> Diferenciar sistemas estruturantes de sistemas acessórios | D29: ='OKR '!E159 -> Grupo de trabalho | E29: ='OKR '!G159 -> 46055 | F29: ='OKR '!H159 -> 46203 | G29: =F29-E29 -> 148 | H29: {=IF($A29="Eixo: 2 - Formação e Desenvolvimento",$G29,_xludf.NA())} -> #NAME? | I29: {=IF($A29="Eixo: 4 - Telessaúde",$G29,_xludf.NA())} -> #NAME? | J29: {=IF($A29="Eixo: 6 - Monitoramento, avaliação e disseminação de informações estratégicas",$G29,_xludf.NA())} -> 148
A30: Eixo: 4 - Telessaúde | B30: Consolidar o uso da telessaúde na microrregião | C30: ='OKR '!D128 -> Elaborar campanha de sensibilização | D30: ='OKR '!E128 -> Equipe Microrregional, SES (Equipe da Telessaúde + NSDIGI), Núcleos de telessaúde | E30: ='OKR '!G128 -> 46082 | F30: ='OKR '!H128 -> 46142 | G30: =F30-E30 -> 60 | H30: {=IF($A30="Eixo: 2 - Formação e Desenvolvimento",$G30,_xludf.NA())} -> #NAME? | I30: {=IF($A30="Eixo: 4 - Telessaúde",$G30,_xludf.NA())} -> 60 | J30: {=IF($A30="Eixo: 6 - Monitoramento, avaliação e disseminação de informações estratégicas",$G30,_xludf.NA())} -> #NAME?
A31: Eixo: 4 - Telessaúde | B31: Consolidar o uso da telessaúde na microrregião | C31: ='OKR '!D129 -> Definir percentual mínimo de membros das equipes habilitados | D31: ='OKR '!E129 -> Equipe Microrregional | E31: ='OKR '!G129 -> 46082 | F31: ='OKR '!H129 -> 46142 | G31: =F31-E31 -> 60 | H31: {=IF($A31="Eixo: 2 - Formação e Desenvolvimento",$G31,_xludf.NA())} -> #NAME? | I31: {=IF($A31="Eixo: 4 - Telessaúde",$G31,_xludf.NA())} -> 60 | J31: {=IF($A31="Eixo: 6 - Monitoramento, avaliação e disseminação de informações estratégicas",$G31,_xludf.NA())} -> #NAME?
A32: Eixo: 2 - Formação e Desenvolvimento | B32: Criar a Governança do GT de Saúde Digital para formação | C32: Formalizar equipe Intersetorial na CIB microrregional | D32: Gestores Municipais | E32: 46083 | F32: 46112 | G32: =F32-E32 -> 29 | H32: {=IF($A32="Eixo: 2 - Formação e Desenvolvimento",$G32,_xludf.NA())} -> 29 | I32: {=IF($A32="Eixo: 4 - Telessaúde",$G32,_xludf.NA())} -> #NAME? | J32: {=IF($A32="Eixo: 6 - Monitoramento, avaliação e disseminação de informações estratégicas",$G32,_xludf.NA())} -> #NAME?
A33: Eixo: 2 - Formação e Desenvolvimento | B33: Criar a Governança do GT de Saúde Digital para formação | C33: Capacitar equipe intersetorial | D33: NSDIGI | E33: 46083 | F33: 46142 | G33: =F33-E33 -> 59 | H33: {=IF($A33="Eixo: 2 - Formação e Desenvolvimento",$G33,_xludf.NA())} -> 59 | I33: {=IF($A33="Eixo: 4 - Telessaúde",$G33,_xludf.NA())} -> #NAME? | J33: {=IF($A33="Eixo: 6 - Monitoramento, avaliação e disseminação de informações estratégicas",$G33,_xludf.NA())} -> #NAME?
A34: Eixo: 2 - Formação e Desenvolvimento | B34: Implementar gestão regional de formações | C34: Identificar necessidades locais e planejar ações. | D34: Grupo de Trabalho | E34: 46113 | F34: 46173 | G34: =F34-E34 -> 60 | H34: {=IF($A34="Eixo: 2 - Formação e Desenvolvimento",$G34,_xludf.NA())} -> 60 | I34: {=IF($A34="Eixo: 4 - Telessaúde",$G34,_xludf.NA())} -> #NAME? | J34: {=IF($A34="Eixo: 6 - Monitoramento, avaliação e disseminação de informações estratégicas",$G34,_xludf.NA())} -> #NAME?
A35: Eixo: 2 - Formação e Desenvolvimento | B35: Implementar gestão regional de formações | C35: Definir portfólio de cursos (fixos e sazionais) | D35: Grupo de Trabalho | E35: 46113 | F35: 46203 | G35: =F35-E35 -> 90 | H35: {=IF($A35="Eixo: 2 - Formação e Desenvolvimento",$G35,_xludf.NA())} -> 90 | I35: {=IF($A35="Eixo: 4 - Telessaúde",$G35,_xludf.NA())} -> #NAME? | J35: {=IF($A35="Eixo: 6 - Monitoramento, avaliação e disseminação de informações estratégicas",$G35,_xludf.NA())} -> #NAME?
A36: Eixo: 2 - Formação e Desenvolvimento | B36: Implementar gestão regional de formações | C36: Solicitar treinamentos conforme necessidades. | D36: Grupo de Trabalho | E36: 46113 | F36: 46387 | G36: =F36-E36 -> 274 | H36: {=IF($A36="Eixo: 2 - Formação e Desenvolvimento",$G36,_xludf.NA())} -> 274 | I36: {=IF($A36="Eixo: 4 - Telessaúde",$G36,_xludf.NA())} -> #NAME? | J36: {=IF($A36="Eixo: 6 - Monitoramento, avaliação e disseminação de informações estratégicas",$G36,_xludf.NA())} -> #NAME?
A37: Eixo: 2 - Formação e Desenvolvimento | B37: Implementar gestão regional de formações | C37: Desenvolver protocolos e indicadores. | D37: Grupo de Trabalho | E37: 46113 | F37: 46173 | G37: =F37-E37 -> 60 | H37: {=IF($A37="Eixo: 2 - Formação e Desenvolvimento",$G37,_xludf.NA())} -> 60 | I37: {=IF($A37="Eixo: 4 - Telessaúde",$G37,_xludf.NA())} -> #NAME? | J37: {=IF($A37="Eixo: 6 - Monitoramento, avaliação e disseminação de informações estratégicas",$G37,_xludf.NA())} -> #NAME?
A38: Eixo: 2 - Formação e Desenvolvimento | B38: Implementar gestão regional de formações | C38: Elaborar modelo avaliação das formações | D38: Grupo de Trabalho | E38: 46113 | F38: 46173 | G38: =F38-E38 -> 60 | H38: {=IF($A38="Eixo: 2 - Formação e Desenvolvimento",$G38,_xludf.NA())} -> 60 | I38: {=IF($A38="Eixo: 4 - Telessaúde",$G38,_xludf.NA())} -> #NAME? | J38: {=IF($A38="Eixo: 6 - Monitoramento, avaliação e disseminação de informações estratégicas",$G38,_xludf.NA())} -> #NAME?
A39: Eixo: 2 - Formação e Desenvolvimento | B39: ='OKR '!D56 -> Realizar 1º ciclo completo de formações | C39: ='OKR '!D59 -> Realizar campanha de sensibilização e mobilização para formações | D39: ='OKR '!E59 -> Grupo de Trabalho; Regional; Gestores Municipais | E39: ='OKR '!G59 -> 46113 | F39: ='OKR '!H59 -> 46173 | G39: =F39-E39 -> 60 | H39: {=IF($A39="Eixo: 2 - Formação e Desenvolvimento",$G39,_xludf.NA())} -> 60 | I39: {=IF($A39="Eixo: 4 - Telessaúde",$G39,_xludf.NA())} -> #NAME? | J39: {=IF($A39="Eixo: 6 - Monitoramento, avaliação e disseminação de informações estratégicas",$G39,_xludf.NA())} -> #NAME?
A40: Eixo: 4 - Telessaúde | B40: Consolidar o uso da telessaúde na microrregião | C40: ='OKR '!D130 -> Preparar material de formação | D40: ='OKR '!E130 -> Equipe Microrregional, SES (Equipe da Telessaúde + NSDIGI), Núcleos de telessaúde | E40: ='OKR '!G130 -> 46113 | F40: ='OKR '!H130 -> 46234 | G40: =F40-E40 -> 121 | H40: {=IF($A40="Eixo: 2 - Formação e Desenvolvimento",$G40,_xludf.NA())} -> #NAME? | I40: {=IF($A40="Eixo: 4 - Telessaúde",$G40,_xludf.NA())} -> 121 | J40: {=IF($A40="Eixo: 6 - Monitoramento, avaliação e disseminação de informações estratégicas",$G40,_xludf.NA())} -> #NAME?
...

Sheet Gantt por eixo
B1: Neste gráfico de Gantt, cada eixo aparece separadamente, com cada ação deste eixo organizada por data de execução. Cada um dos eixos a ser trabalhado está identificado por cores, quais sejam:
B2: Este gráfico de Gantt está organizado por data de execução, independente da segmentação por eixo. As ações de cada eixo a ser trabalhado estão identificadas por cores, quais sejam:
B3: Eixo: 2 - Formação e Desenvolvimento | I3: Eixo 4 - Telessaúde | P3: Eixo: 6 - Monitoramento, avaliação e disseminação de informações estratégicas

Sheet Gantt
A1: Crie um cronograma de projeto nesta planilha. Digite o título desse projeto na célula B1. As informações sobre como usar esta planilha, incluindo instruções para leitores de tela e o autor desta pasta de trabalho, estão na planilha Sobre. Continue navegando pela coluna A para saber mais. | B1: ='OKR '!C6 -> MICRORREGIÃO BELO HORIZONTE/NOVA LIMA/SANTA LUZIA | I1: GRÁFICO DE GANTT SIMPLES por Vertex42.com
A2: Insira o Nome da empresa na célula B2. | I2: https://www.vertex42.com/ExcelTemplates/simple-gantt-chart.html
A3: Insira o nome do Líder do projeto na célula B3. Insira a data de Início do projeto na célula E3. Início do projeto: o rótulo está na célula C3. | C3: Início do projeto: | E3: 46055
A4: A semana de exibição na célula E4 representa a semana inicial a ser exibida no cronograma do projeto na célula I4. A data de início do projeto é considerada Semana 1. Para alterar a semana de exibição, basta inserir um novo número da semana na célula E4. A data inicial para cada semana, começando com a semana de exibição na célula E4, começa na célula I4 e é calculada automaticamente. Há 8 semanas representadas nesse modo de exibição que vão da célula I4 a célula BF4. Você não deve modificar essas células. Semana de exibição: o rótulo está na célula C4. | C4: Semana de exibição: | E4: 1 | I4: =I5 -> 46055 | P4: =P5 -> 46062 | W4: =W5 -> 46069 | AD4: =AD5 -> 46076 | AK4: =AK5 -> 46083 | AR4: =AR5 -> 46090 | AY4: =AY5 -> 46097 | BF4: =BF5 -> 46104 | BM4: =BM5 -> 46111 | BT4: =BT5 -> 46118 | CA4: =CA5 -> 46125 | CH4: =CH5 -> 46132 | CO4: =CO5 -> 46139 | CV4: =CV5 -> 46146 | DC4: =DC5 -> 46153 | DJ4: =DJ5 -> 46160 | DQ4: =DQ5 -> 46167 | DX4: =DX5 -> 46174 | EE4: =EE5 -> 46181 | EL4: =EL5 -> 46188 | ES4: =ES5 -> 46195 | EZ4: =EZ5 -> 46202 | FG4: =FG5 -> 46209 | FN4: =FN5 -> 46216 | FU4: =FU5 -> 46223 | GB4: =GB5 -> 46230 | GI4: =GI5 -> 46237 | GP4: =GP5 -> 46244 | GW4: =GW5 -> 46251 | HD4: =HD5 -> 46258 | HK4: =HK5 -> 46265 | HR4: =HR5 -> 46272 | HY4: =HY5 -> 46279 | IF4: =IF5 -> 46286 | IM4: =IM5 -> 46293 | IT4: =IT5 -> 46300 | JA4: =JA5 -> 46307 | JH4: =JH5 -> 46314 | JO4: =JO5 -> 46321 | JV4: =JV5 -> 46328 | KC4: =KC5 -> 46335 | KJ4: =KJ5 -> 46342 | KQ4: =KQ5 -> 46349 | KX4: =KX5 -> 46356 | LE4: =LE5 -> 46363 | LL4: =LL5 -> 46370 | LS4: =LS5 -> 46377 | LZ4: =LZ5 -> 46384
A5: As células I5 a BL5 contêm o número de dias da semana representado no bloco de células acima de cada célula de data e são calculadas automaticamente. Você não deve modificar essas células. A data de hoje é contornada em vermelho (hex #AD3815) a partir da data de hoje na linha 5, passando pela coluna de data inteira até o final do cronograma do projeto. | I5: =Início_do_projeto-WEEKDAY(Início_do_projeto,1)+2+7*(Semana_de_exibição-1) -> 46055 | J5: =I5+1 -> 46056 | K5: =J5+1 -> 46057 | L5: =K5+1 -> 46058 | M5: =L5+1 -> 46059 | N5: =M5+1 -> 46060 | O5: =N5+1 -> 46061 | P5: =O5+1 -> 46062 | Q5: =P5+1 -> 46063 | ... MF5: =ME5+1 -> 46390
A6: Esta linha inclui cabeçalhos do cronograma do projeto que estão abaixo deles. Navegue de B6 a BL6 para ouvir o conteúdo. A primeira letra de cada dia da semana da data acima daquele cabeçalho começa na célula I6 e continua até a célula BL6. Todo o gráfico de linha do tempo de projeto é gerado automaticamente com base nas datas de início e término inseridas, usando os formatos condicionais. Não modifique o conteúdo nas células dentro das colunas após a coluna I, começando na célula I7. | B6: ='OKR '!D10 -> Implementar um GT de Saúde Digital microrregional para formação dos profissionais de saúde | C6: Áreas envolvidas | D6: PROGRESSO | E6: INÍCIO | F6: TÉRMINO | H6: DIAS | I6: =LEFT(TEXT(I5,"ddd"),1) -> s | J6: =LEFT(TEXT(J5,"ddd"),1) -> t | K6: =LEFT(TEXT(K5,"ddd"),1) -> q | L6: =LEFT(TEXT(L5,"ddd"),1) -> q | M6: =LEFT(TEXT(M5,"ddd"),1) -> s | N6: =LEFT(TEXT(N5,"ddd"),1) -> s | O6: =LEFT(TEXT(O5,"ddd"),1) -> d | P6: =LEFT(TEXT(P5,"ddd"),1) -> s | ... MF6: =LEFT(TEXT(MF5,"ddd"),1) -> d
A7: Não exclua esta linha. Esta linha ficará oculta para preservar uma fórmula usada para realçar o dia atual no cronograma do projeto. | H7: =IF(OR(ISBLANK(início_da_tarefa),ISBLANK(término_da_tarefa)),"",término_da_tarefa-início_da_tarefa+1)
A8: A célula B8 contém o título do exemplo da Fase 1. Insira um novo Título na célula B8. Na célula C8, insira o nome a atribuir à fase, caso ela se aplique ao seu projeto. Na célula D8, insira o Progresso para a fase inteira, caso ela se aplique ao seu projeto. Nas células E8 e F8, insira as datas de início e término para a fase inteira, caso ela se aplique ao seu projeto. O gráfico de Gantt preenche automaticamente as datas apropriadas e sombreia de acordo com o andamento inserido. Para excluir a fase e trabalhar apenas nas tarefas, basta excluir essa linha. | B8: ='OKR '!D20 -> Criar a Governança do GT de Saúde Digital para formação | H8: =IF(OR(ISBLANK(início_da_tarefa),ISBLANK(término_da_tarefa)),"",término_da_tarefa-início_da_tarefa+1)
A9: A célula B9 contém a tarefa de exemplo "Tarefa 1". Insira um novo nome da tarefa na célula B9. Insira uma pessoa para atribuir a tarefa na célula C9. Insira o andamento da tarefa na célula D9. Uma barra de progresso é exibida na célula e fica sombreada de acordo com o número na célula. Por exemplo, 50% de progresso sombreia metade da célula. Insira a data de início da tarefa na célula E9. Insira a data de término da tarefa na célula F9. Uma barra de status sombreada das datas inseridas aparece em blocos começando na célula I9 até BL9. | B9: ='OKR '!D23 -> Definir escopo do grupo (responsabilidades, atribuições, frequência das reuniões, governança) | C9: ='OKR '!E23 -> SMS, NSDIGI, Regional, Cosems | E9: ='OKR '!G23 -> 46055 | F9: ='OKR '!H23 -> 46080 | H9: =IF(OR(ISBLANK(início_da_tarefa),ISBLANK(término_da_tarefa)),"",término_da_tarefa-início_da_tarefa+1) -> 26
A10: As linhas 10 a 13 repetem o padrão da linha 9. Repita as instruções da célula A9 para todas as linhas de tarefas nesta planilha. Substitua os dados de exemplo. Um exemplo de outra fase começa na célula A14. Continue inserindo tarefas nas células A10 a A13 ou vá para a célula A14 para saber mais. | B10: ='OKR '!D24 -> Indicar representantes | C10: ='OKR '!E24 -> Gestores Municipais | E10: ='OKR '!G24 -> 46055 | F10: ='OKR '!H24 -> 46080 | H10: =IF(OR(ISBLANK(início_da_tarefa),ISBLANK(término_da_tarefa)),"",término_da_tarefa-início_da_tarefa+1) -> 26
B11: ='OKR '!D25 -> Formalizar equipe Intersetorial na CIB microrregional | C11: ='OKR '!E25 -> Gestores Municipais | E11: ='OKR '!G25 -> 46083 | F11: ='OKR '!H25 -> 46112 | H11: =IF(OR(ISBLANK(início_da_tarefa),ISBLANK(término_da_tarefa)),"",término_da_tarefa-início_da_tarefa+1) -> 30
B12: ='OKR '!D26 -> Capacitar equipe intersetorial | C12: ='OKR '!E26 -> NSDIGI | E12: ='OKR '!G26 -> 46083 | F12: ='OKR '!H26 -> 46142 | H12: =IF(OR(ISBLANK(início_da_tarefa),ISBLANK(término_da_tarefa)),"",término_da_tarefa-início_da_tarefa+1) -> 60
B13: ='OKR '!D27 -> 0 | C13: ='OKR '!E27 -> 0 | E13: ='OKR '!G27 -> 0 | F13: ='OKR '!H27 -> 0 | H13: =IF(OR(ISBLANK(início_da_tarefa),ISBLANK(término_da_tarefa)),"",término_da_tarefa-início_da_tarefa+1) -> 1
B14: ='OKR '!D28 -> 0 | C14: ='OKR '!E28 -> 0 | E14: ='OKR '!G28 -> 0 | F14: ='OKR '!H28 -> 0
B15: ='OKR '!D29 -> 0 | C15: ='OKR '!E29 -> 0 | E15: ='OKR '!G29 -> 0 | F15: ='OKR '!H29 -> 0
B16: ='OKR '!D30 -> 0 | C16: ='OKR '!E30 -> 0 | E16: ='OKR '!G30 -> 0 | F16: ='OKR '!H30 -> 0
B17: ='OKR '!D31 -> 0 | C17: ='OKR '!E31 -> 0 | E17: ='OKR '!G31 -> 0 | F17: ='OKR '!H31 -> 0
B18: ='OKR '!D32 -> 0 | C18: ='OKR '!E32 -> 0 | E18: ='OKR '!G32 -> 0 | F18: ='OKR '!H32 -> 0
B19: ='OKR '!D33 -> 0 | C19: ='OKR '!E33 -> 0 | E19: ='OKR '!G33 -> 0 | F19: ='OKR '!H33 -> 0
B20: ='OKR '!D34 -> 0 | C20: ='OKR '!E34 -> 0 | E20: ='OKR '!G34 -> 0 | F20: ='OKR '!H34 -> 0
A21: A célula à direita contém o título do exemplo da Fase 2. Você pode criar uma nova fase a qualquer momento na coluna B. Este cronograma de projeto não exige fases. Para remover a fase, basta excluir a linha. Para criar um novo bloco de fases nesta linha, digite um novo Título na célula à direita. Para continuar a adicionar tarefas à fase acima, insira uma nova linha acima desta e preencha os dados da tarefa como na instrução da célula A9. Atualize os detalhes da Fase na célula à direita, com base nas instruções da célula A8. Continue navegando para baixo nas células da coluna A para saber mais. Se você ainda não adicionou as novas linhas nesta planilha, encontrará 2 exemplos adicionais de blocos de fase que foram criados nas células B20 e B26. Caso contrário, navegue pelas células da coluna A para localizar os blocos adicionais. Repita as instruções das células A8 e A9 sempre que precisar. | B21: ='OKR '!D37 -> Implementar gestão regional de formações | H21: =IF(OR(ISBLANK(início_da_tarefa),ISBLANK(término_da_tarefa)),"",término_da_tarefa-início_da_tarefa+1)
B22: ='OKR '!D40 -> Avaliar dados do Valorizagtes-sus | C22: ='OKR '!E40 -> Grupo de Trabalho | E22: ='OKR '!G40 -> 46055 | F22: ='OKR '!H40 -> 46142
B23: ='OKR '!D41 -> Avaliar diagnóstico de demanda por formações do Valoriza SUS | C23: ='OKR '!E41 -> Grupo de Trabalho | E23: ='OKR '!G41 -> 46055 | F23: ='OKR '!H41 -> 46142 | H23: =IF(OR(ISBLANK(início_da_tarefa),ISBLANK(término_da_tarefa)),"",término_da_tarefa-início_da_tarefa+1) -> 88
B24: ='OKR '!D42 -> Avaliar a inclusão da temática de Saúde Digital no Valoriza SUS | C24: ='OKR '!E42 -> Grupo de Trabalho | E24: ='OKR '!G42 -> 46055 | F24: ='OKR '!H42 -> 46142 | H24: =IF(OR(ISBLANK(início_da_tarefa),ISBLANK(término_da_tarefa)),"",término_da_tarefa-início_da_tarefa+1) -> 88
B25: ='OKR '!D43 -> Criar rotina regional de formação | C25: ='OKR '!E43 -> Grupo de Trabalho | E25: ='OKR '!G43 -> 46054 | F25: ='OKR '!H43 -> 46142 | H25: =IF(OR(ISBLANK(início_da_tarefa),ISBLANK(término_da_tarefa)),"",término_da_tarefa-início_da_tarefa+1) -> 89
B26: ='OKR '!D44 -> Identificar necessidades locais e planejar ações. | C26: ='OKR '!E44 -> Grupo de Trabalho | E26: ='OKR '!G44 -> 46113 | F26: ='OKR '!H44 -> 46173 | H26: =IF(OR(ISBLANK(início_da_tarefa),ISBLANK(término_da_tarefa)),"",término_da_tarefa-início_da_tarefa+1) -> 61
B27: ='OKR '!D45 -> Desenvolver protocolos e indicadores. | C27: ='OKR '!E45 -> Grupo de Trabalho | E27: ='OKR '!G45 -> 46113 | F27: ='OKR '!H45 -> 46173
B28: ='OKR '!D46 -> Elaborar modelo avaliação das formações | C28: ='OKR '!E46 -> Grupo de Trabalho | E28: ='OKR '!G46 -> 46113 | F28: ='OKR '!H46 -> 46173
B29: ='OKR '!D47 -> Definir portfólio de cursos (fixos e sazionais) | C29: ='OKR '!E47 -> Grupo de Trabalho | E29: ='OKR '!G47 -> 46113 | F29: ='OKR '!H47 -> 46203
B30: ='OKR '!D48 -> Solicitar treinamentos conforme necessidades. | C30: ='OKR '!E48 -> Grupo de Trabalho | E30: ='OKR '!G48 -> 46113 | F30: ='OKR '!H48 -> 46387 | H30: =IF(OR(ISBLANK(início_da_tarefa),ISBLANK(término_da_tarefa)),"",término_da_tarefa-início_da_tarefa+1) -> 275
B31: ='OKR '!D49 -> Apresentar resultados das qualificações - CIB Micro | C31: ='OKR '!E49 -> Grupo de Trabalho | E31: ='OKR '!G49 -> 46327 | F31: ='OKR '!H49 -> 46356
B32: ='OKR '!D50 -> 0 | C32: ='OKR '!E50 -> 0 | E32: ='OKR '!G50 -> 0 | F32: ='OKR '!H50 -> 0
B33: ='OKR '!D51 -> 0 | C33: ='OKR '!E51 -> 0 | E33: ='OKR '!G51 -> 0 | F33: ='OKR '!H51 -> 0
A34: Bloco de título de fase de exemplo | B34: ='OKR '!D56 -> Realizar 1º ciclo completo de formações | H34: =IF(OR(ISBLANK(início_da_tarefa),ISBLANK(término_da_tarefa)),"",término_da_tarefa-início_da_tarefa+1)
B35: ='OKR '!D59 -> Realizar campanha de sensibilização e mobilização para formações | C35: ='OKR '!E59 -> Grupo de Trabalho; Regional; Gestores Municipais | E35: ='OKR '!G59 -> 46113 | F35: ='OKR '!H59 -> 46173 | H35: =IF(OR(ISBLANK(início_da_tarefa),ISBLANK(término_da_tarefa)),"",término_da_tarefa-início_da_tarefa+1) -> 61
B36: ='OKR '!D60 -> Realizar formações priorizadas | C36: ='OKR '!E60 -> Grupo de Trabalho, Regional, Gestores Municipais, NSDIGI, Grupo de Telessaúde e Gestão de Dados | E36: ='OKR '!G60 -> 46143 | F36: ='OKR '!H60 -> 46234 | H36: =IF(OR(ISBLANK(início_da_tarefa),ISBLANK(término_da_tarefa)),"",término_da_tarefa-início_da_tarefa+1) -> 92
B37: ='OKR '!D61 -> Aplicar avaliação | C37: ='OKR '!E61 -> Grupo de Trabalho | E37: ='OKR '!G61 -> 46235 | F37: ='OKR '!H61 -> 46265 | H37: =IF(OR(ISBLANK(início_da_tarefa),ISBLANK(término_da_tarefa)),"",término_da_tarefa-início_da_tarefa+1) -> 31
B38: ='OKR '!D62 -> Definir uma rede de apoio pós-treinamentos. | C38: ='OKR '!E62 -> Grupo de Trabalho | E38: ='OKR '!G62 -> 46235 | F38: ='OKR '!H62 -> 46325 | H38: =IF(OR(ISBLANK(início_da_tarefa),ISBLANK(término_da_tarefa)),"",término_da_tarefa-início_da_tarefa+1) -> 91
B39: ='OKR '!D63 -> 0 | C39: ='OKR '!E63 -> 0 | E39: ='OKR '!G63 -> 0 | F39: ='OKR '!H63 -> 0
B40: ='OKR '!D64 -> 0 | C40: ='OKR '!E64 -> 0 | E40: ='OKR '!G64 -> 0 | F40: ='OKR '!H64 -> 0
...

Sheet Telessaúde
A1: Crie um cronograma de projeto nesta planilha. Digite o título desse projeto na célula B1. As informações sobre como usar esta planilha, incluindo instruções para leitores de tela e o autor desta pasta de trabalho, estão na planilha Sobre. Continue navegando pela coluna A para saber mais. | B1: Desenhar e institucionalizar a estratégia de Telessaúde no município. | I1: GRÁFICO DE GANTT SIMPLES por Vertex42.com
A2: Insira o Nome da empresa na célula B2. | B2: Micro Pouso Alegre | I2: https://www.vertex42.com/ExcelTemplates/simple-gantt-chart.html
A3: Insira o nome do Líder do projeto na célula B3. Insira a data de Início do projeto na célula E3. Início do projeto: o rótulo está na célula C3. | B3: NSDIGI | C3: Início do projeto: | E3: =TODAY() -> 46148
A4: A semana de exibição na célula E4 representa a semana inicial a ser exibida no cronograma do projeto na célula I4. A data de início do projeto é considerada Semana 1. Para alterar a semana de exibição, basta inserir um novo número da semana na célula E4. A data inicial para cada semana, começando com a semana de exibição na célula E4, começa na célula I4 e é calculada automaticamente. Há 8 semanas representadas nesse modo de exibição que vão da célula I4 a célula BF4. Você não deve modificar essas células. Semana de exibição: o rótulo está na célula C4. | C4: Semana de exibição: | E4: 1 | I4: =I5 -> 46146 | P4: =P5 -> 46153 | W4: =W5 -> 46160 | AD4: =AD5 -> 46167 | AK4: =AK5 -> 46174 | AR4: =AR5 -> 46181 | AY4: =AY5 -> 46188 | BF4: =BF5 -> 46195
A5: As células I5 a BL5 contêm o número de dias da semana representado no bloco de células acima de cada célula de data e são calculadas automaticamente. Você não deve modificar essas células. A data de hoje é contornada em vermelho (hex #AD3815) a partir da data de hoje na linha 5, passando pela coluna de data inteira até o final do cronograma do projeto. | I5: =Início_do_projeto-WEEKDAY(Início_do_projeto,1)+2+7*(Semana_de_exibição-1) -> 46146 | J5: =I5+1 -> 46147 | K5: =J5+1 -> 46148 | L5: =K5+1 -> 46149 | M5: =L5+1 -> 46150 | N5: =M5+1 -> 46151 | O5: =N5+1 -> 46152 | P5: =O5+1 -> 46153 | Q5: =P5+1 -> 46154 | ... BL5: =BK5+1 -> 46201
A6: Esta linha inclui cabeçalhos do cronograma do projeto que estão abaixo deles. Navegue de B6 a BL6 para ouvir o conteúdo. A primeira letra de cada dia da semana da data acima daquele cabeçalho começa na célula I6 e continua até a célula BL6. Todo o gráfico de linha do tempo de projeto é gerado automaticamente com base nas datas de início e término inseridas, usando os formatos condicionais. Não modifique o conteúdo nas células dentro das colunas após a coluna I, começando na célula I7. | B6: TAREFA | C6: Áreas envolvidas | D6: PROGRESSO | E6: INÍCIO | F6: TÉRMINO | H6: DIAS | I6: =LEFT(TEXT(I5,"ddd"),1) -> s | J6: =LEFT(TEXT(J5,"ddd"),1) -> t | K6: =LEFT(TEXT(K5,"ddd"),1) -> q | L6: =LEFT(TEXT(L5,"ddd"),1) -> q | M6: =LEFT(TEXT(M5,"ddd"),1) -> s | N6: =LEFT(TEXT(N5,"ddd"),1) -> s | O6: =LEFT(TEXT(O5,"ddd"),1) -> d | P6: =LEFT(TEXT(P5,"ddd"),1) -> s | ... BL6: =LEFT(TEXT(BL5,"ddd"),1) -> d
A7: Não exclua esta linha. Esta linha ficará oculta para preservar uma fórmula usada para realçar o dia atual no cronograma do projeto. | H7: =IF(OR(ISBLANK(início_da_tarefa),ISBLANK(término_da_tarefa)),"",término_da_tarefa-início_da_tarefa+1)
A8: A célula B8 contém o título do exemplo da Fase 1. Insira um novo Título na célula B8. Na célula C8, insira o nome a atribuir à fase, caso ela se aplique ao seu projeto. Na célula D8, insira o Progresso para a fase inteira, caso ela se aplique ao seu projeto. Nas células E8 e F8, insira as datas de início e término para a fase inteira, caso ela se aplique ao seu projeto. O gráfico de Gantt preenche automaticamente as datas apropriadas e sombreia de acordo com o andamento inserido. Para excluir a fase e trabalhar apenas nas tarefas, basta excluir essa linha. | B8: ATV 1 - PLANEJAMENTO E ESTRUTURAÇÃO | H8: =IF(OR(ISBLANK(início_da_tarefa),ISBLANK(término_da_tarefa)),"",término_da_tarefa-início_da_tarefa+1)
A9: A célula B9 contém a tarefa de exemplo "Tarefa 1". Insira um novo nome da tarefa na célula B9. Insira uma pessoa para atribuir a tarefa na célula C9. Insira o andamento da tarefa na célula D9. Uma barra de progresso é exibida na célula e fica sombreada de acordo com o número na célula. Por exemplo, 50% de progresso sombreia metade da célula. Insira a data de início da tarefa na célula E9. Insira a data de término da tarefa na célula F9. Uma barra de status sombreada das datas inseridas aparece em blocos começando na célula I9 até BL9. | B9: Ação | C9: Nome | D9: 0.5 | E9: =Início_do_projeto -> 46148 | F9: =E9+3 -> 46151 | H9: =IF(OR(ISBLANK(início_da_tarefa),ISBLANK(término_da_tarefa)),"",término_da_tarefa-início_da_tarefa+1) -> 4
A10: As linhas 10 a 13 repetem o padrão da linha 9. Repita as instruções da célula A9 para todas as linhas de tarefas nesta planilha. Substitua os dados de exemplo. Um exemplo de outra fase começa na célula A14. Continue inserindo tarefas nas células A10 a A13 ou vá para a célula A14 para saber mais. | B10: Ação | D10: 0.6 | E10: =F9 -> 46151 | F10: =E10+2 -> 46153 | H10: =IF(OR(ISBLANK(início_da_tarefa),ISBLANK(término_da_tarefa)),"",término_da_tarefa-início_da_tarefa+1) -> 3
B11: Ação | D11: 0.5 | E11: =F10 -> 46153 | F11: =E11+4 -> 46157 | H11: =IF(OR(ISBLANK(início_da_tarefa),ISBLANK(término_da_tarefa)),"",término_da_tarefa-início_da_tarefa+1) -> 5
B12: Ação | D12: 0.25 | E12: =F11 -> 46157 | F12: =E12+5 -> 46162 | H12: =IF(OR(ISBLANK(início_da_tarefa),ISBLANK(término_da_tarefa)),"",término_da_tarefa-início_da_tarefa+1) -> 6
B13: Ação | E13: =E10+1 -> 46152 | F13: =E13+2 -> 46154 | H13: =IF(OR(ISBLANK(início_da_tarefa),ISBLANK(término_da_tarefa)),"",término_da_tarefa-início_da_tarefa+1) -> 3
A14: A célula à direita contém o título do exemplo da Fase 2. Você pode criar uma nova fase a qualquer momento na coluna B. Este cronograma de projeto não exige fases. Para remover a fase, basta excluir a linha. Para criar um novo bloco de fases nesta linha, digite um novo Título na célula à direita. Para continuar a adicionar tarefas à fase acima, insira uma nova linha acima desta e preencha os dados da tarefa como na instrução da célula A9. Atualize os detalhes da Fase na célula à direita, com base nas instruções da célula A8. Continue navegando para baixo nas células da coluna A para saber mais. Se você ainda não adicionou as novas linhas nesta planilha, encontrará 2 exemplos adicionais de blocos de fase que foram criados nas células B20 e B26. Caso contrário, navegue pelas células da coluna A para localizar os blocos adicionais. Repita as instruções das células A8 e A9 sempre que precisar. | B14: Título Fase 2 | H14: =IF(OR(ISBLANK(início_da_tarefa),ISBLANK(término_da_tarefa)),"",término_da_tarefa-início_da_tarefa+1)
B15: Tarefa 1 | D15: 0.5 | E15: =E13+1 -> 46153 | F15: =E15+4 -> 46157 | H15: =IF(OR(ISBLANK(início_da_tarefa),ISBLANK(término_da_tarefa)),"",término_da_tarefa-início_da_tarefa+1) -> 5
B16: Tarefa 2 | D16: 0.5 | E16: =E15+2 -> 46155 | F16: =E16+5 -> 46160 | H16: =IF(OR(ISBLANK(início_da_tarefa),ISBLANK(término_da_tarefa)),"",término_da_tarefa-início_da_tarefa+1) -> 6
B17: Tarefa 3 | E17: =F16 -> 46160 | F17: =E17+3 -> 46163 | H17: =IF(OR(ISBLANK(início_da_tarefa),ISBLANK(término_da_tarefa)),"",término_da_tarefa-início_da_tarefa+1) -> 4
B18: Tarefa 4 | E18: =E17 -> 46160 | F18: =E18+2 -> 46162 | H18: =IF(OR(ISBLANK(início_da_tarefa),ISBLANK(término_da_tarefa)),"",término_da_tarefa-início_da_tarefa+1) -> 3
B19: Tarefa 5 | E19: =E18 -> 46160 | F19: =E19+3 -> 46163 | H19: =IF(OR(ISBLANK(início_da_tarefa),ISBLANK(término_da_tarefa)),"",término_da_tarefa-início_da_tarefa+1) -> 4
A20: Bloco de título de fase de exemplo | B20: Título Fase 3 | H20: =IF(OR(ISBLANK(início_da_tarefa),ISBLANK(término_da_tarefa)),"",término_da_tarefa-início_da_tarefa+1)
B21: Tarefa 1 | E21: =E9+15 -> 46163 | F21: =E21+5 -> 46168 | H21: =IF(OR(ISBLANK(início_da_tarefa),ISBLANK(término_da_tarefa)),"",término_da_tarefa-início_da_tarefa+1) -> 6
B22: Tarefa 2 | E22: =F21+1 -> 46169 | F22: =E22+4 -> 46173 | H22: =IF(OR(ISBLANK(início_da_tarefa),ISBLANK(término_da_tarefa)),"",término_da_tarefa-início_da_tarefa+1) -> 5
B23: Tarefa 3 | E23: =E22+5 -> 46174 | F23: =E23+5 -> 46179 | H23: =IF(OR(ISBLANK(início_da_tarefa),ISBLANK(término_da_tarefa)),"",término_da_tarefa-início_da_tarefa+1) -> 6
B24: Tarefa 4 | E24: =F23+1 -> 46180 | F24: =E24+4 -> 46184 | H24: =IF(OR(ISBLANK(início_da_tarefa),ISBLANK(término_da_tarefa)),"",término_da_tarefa-início_da_tarefa+1) -> 5
B25: Tarefa 5 | E25: =E23 -> 46174 | F25: =E25+4 -> 46178 | H25: =IF(OR(ISBLANK(início_da_tarefa),ISBLANK(término_da_tarefa)),"",término_da_tarefa-início_da_tarefa+1) -> 5
A26: Bloco de título de fase de exemplo | B26: Título Fase 4 | H26: =IF(OR(ISBLANK(início_da_tarefa),ISBLANK(término_da_tarefa)),"",término_da_tarefa-início_da_tarefa+1)
B27: Tarefa 1 | E27: data | F27: data | H27: =IF(OR(ISBLANK(início_da_tarefa),ISBLANK(término_da_tarefa)),"",término_da_tarefa-início_da_tarefa+1) -> #VALUE!
B28: Tarefa 2 | E28: data | F28: data | H28: =IF(OR(ISBLANK(início_da_tarefa),ISBLANK(término_da_tarefa)),"",término_da_tarefa-início_da_tarefa+1) -> #VALUE!
B29: Tarefa 3 | E29: data | F29: data | H29: =IF(OR(ISBLANK(início_da_tarefa),ISBLANK(término_da_tarefa)),"",término_da_tarefa-início_da_tarefa+1) -> #VALUE!
B30: Tarefa 4 | E30: data | F30: data | H30: =IF(OR(ISBLANK(início_da_tarefa),ISBLANK(término_da_tarefa)),"",término_da_tarefa-início_da_tarefa+1) -> #VALUE!
B31: Tarefa 5 | E31: data | F31: data | H31: =IF(OR(ISBLANK(início_da_tarefa),ISBLANK(término_da_tarefa)),"",término_da_tarefa-início_da_tarefa+1) -> #VALUE!
A32: Esta é uma linha vazia | H32: =IF(OR(ISBLANK(início_da_tarefa),ISBLANK(término_da_tarefa)),"",término_da_tarefa-início_da_tarefa+1)
A33: Esta linha marca o final do Cronograma do projeto. NÃO insira nada nessa linha. Insira novas linhas ACIMA desta linha para continuar a construção do cronograma de projeto. | B33: Insira novas linhas ACIMA desta | H33: =IF(OR(ISBLANK(início_da_tarefa),ISBLANK(término_da_tarefa)),"",término_da_tarefa-início_da_tarefa+1)

Sheet Infoestrutura
A1: Crie um cronograma de projeto nesta planilha. Digite o título desse projeto na célula B1. As informações sobre como usar esta planilha, incluindo instruções para leitores de tela e o autor desta pasta de trabalho, estão na planilha Sobre. Continue navegando pela coluna A para saber mais. | B1: TÍTULO DO PROJETO | I1: GRÁFICO DE GANTT SIMPLES por Vertex42.com
A2: Insira o Nome da empresa na célula B2. | B2: Nome da empresa | I2: https://www.vertex42.com/ExcelTemplates/simple-gantt-chart.html
A3: Insira o nome do Líder do projeto na célula B3. Insira a data de Início do projeto na célula E3. Início do projeto: o rótulo está na célula C3. | B3: Líder do projeto | C3: Início do projeto: | E3: =TODAY() -> 46148
A4: A semana de exibição na célula E4 representa a semana inicial a ser exibida no cronograma do projeto na célula I4. A data de início do projeto é considerada Semana 1. Para alterar a semana de exibição, basta inserir um novo número da semana na célula E4. A data inicial para cada semana, começando com a semana de exibição na célula E4, começa na célula I4 e é calculada automaticamente. Há 8 semanas representadas nesse modo de exibição que vão da célula I4 a célula BF4. Você não deve modificar essas células. Semana de exibição: o rótulo está na célula C4. | C4: Semana de exibição: | E4: 1 | I4: =I5 -> 46146 | P4: =P5 -> 46153 | W4: =W5 -> 46160 | AD4: =AD5 -> 46167 | AK4: =AK5 -> 46174 | AR4: =AR5 -> 46181 | AY4: =AY5 -> 46188 | BF4: =BF5 -> 46195
A5: As células I5 a BL5 contêm o número de dias da semana representado no bloco de células acima de cada célula de data e são calculadas automaticamente. Você não deve modificar essas células. A data de hoje é contornada em vermelho (hex #AD3815) a partir da data de hoje na linha 5, passando pela coluna de data inteira até o final do cronograma do projeto. | I5: =Início_do_projeto-WEEKDAY(Início_do_projeto,1)+2+7*(Semana_de_exibição-1) -> 46146 | J5: =I5+1 -> 46147 | K5: =J5+1 -> 46148 | L5: =K5+1 -> 46149 | M5: =L5+1 -> 46150 | N5: =M5+1 -> 46151 | O5: =N5+1 -> 46152 | P5: =O5+1 -> 46153 | Q5: =P5+1 -> 46154 | ... BL5: =BK5+1 -> 46201
A6: Esta linha inclui cabeçalhos do cronograma do projeto que estão abaixo deles. Navegue de B6 a BL6 para ouvir o conteúdo. A primeira letra de cada dia da semana da data acima daquele cabeçalho começa na célula I6 e continua até a célula BL6. Todo o gráfico de linha do tempo de projeto é gerado automaticamente com base nas datas de início e término inseridas, usando os formatos condicionais. Não modifique o conteúdo nas células dentro das colunas após a coluna I, começando na célula I7. | B6: TAREFA | C6: Áreas envolvidas | D6: PROGRESSO | E6: INÍCIO | F6: TÉRMINO | H6: DIAS | I6: =LEFT(TEXT(I5,"ddd"),1) -> s | J6: =LEFT(TEXT(J5,"ddd"),1) -> t | K6: =LEFT(TEXT(K5,"ddd"),1) -> q | L6: =LEFT(TEXT(L5,"ddd"),1) -> q | M6: =LEFT(TEXT(M5,"ddd"),1) -> s | N6: =LEFT(TEXT(N5,"ddd"),1) -> s | O6: =LEFT(TEXT(O5,"ddd"),1) -> d | P6: =LEFT(TEXT(P5,"ddd"),1) -> s | ... BL6: =LEFT(TEXT(BL5,"ddd"),1) -> d
A7: Não exclua esta linha. Esta linha ficará oculta para preservar uma fórmula usada para realçar o dia atual no cronograma do projeto. | H7: =IF(OR(ISBLANK(início_da_tarefa),ISBLANK(término_da_tarefa)),"",término_da_tarefa-início_da_tarefa+1)
A8: A célula B8 contém o título do exemplo da Fase 1. Insira um novo Título na célula B8. Na célula C8, insira o nome a atribuir à fase, caso ela se aplique ao seu projeto. Na célula D8, insira o Progresso para a fase inteira, caso ela se aplique ao seu projeto. Nas células E8 e F8, insira as datas de início e término para a fase inteira, caso ela se aplique ao seu projeto. O gráfico de Gantt preenche automaticamente as datas apropriadas e sombreia de acordo com o andamento inserido. Para excluir a fase e trabalhar apenas nas tarefas, basta excluir essa linha. | B8: Atividade 1 XXXXX | H8: =IF(OR(ISBLANK(início_da_tarefa),ISBLANK(término_da_tarefa)),"",término_da_tarefa-início_da_tarefa+1)
A9: A célula B9 contém a tarefa de exemplo "Tarefa 1". Insira um novo nome da tarefa na célula B9. Insira uma pessoa para atribuir a tarefa na célula C9. Insira o andamento da tarefa na célula D9. Uma barra de progresso é exibida na célula e fica sombreada de acordo com o número na célula. Por exemplo, 50% de progresso sombreia metade da célula. Insira a data de início da tarefa na célula E9. Insira a data de término da tarefa na célula F9. Uma barra de status sombreada das datas inseridas aparece em blocos começando na célula I9 até BL9. | B9: Ação | C9: Nome | D9: 0.5 | E9: =Início_do_projeto -> 46148 | F9: =E9+3 -> 46151 | H9: =IF(OR(ISBLANK(início_da_tarefa),ISBLANK(término_da_tarefa)),"",término_da_tarefa-início_da_tarefa+1) -> 4
A10: As linhas 10 a 13 repetem o padrão da linha 9. Repita as instruções da célula A9 para todas as linhas de tarefas nesta planilha. Substitua os dados de exemplo. Um exemplo de outra fase começa na célula A14. Continue inserindo tarefas nas células A10 a A13 ou vá para a célula A14 para saber mais. | B10: Ação | D10: 0.6 | E10: =F9 -> 46151 | F10: =E10+2 -> 46153 | H10: =IF(OR(ISBLANK(início_da_tarefa),ISBLANK(término_da_tarefa)),"",término_da_tarefa-início_da_tarefa+1) -> 3
B11: Ação | D11: 0.5 | E11: =F10 -> 46153 | F11: =E11+4 -> 46157 | H11: =IF(OR(ISBLANK(início_da_tarefa),ISBLANK(término_da_tarefa)),"",término_da_tarefa-início_da_tarefa+1) -> 5
B12: Ação | D12: 0.25 | E12: =F11 -> 46157 | F12: =E12+5 -> 46162 | H12: =IF(OR(ISBLANK(início_da_tarefa),ISBLANK(término_da_tarefa)),"",término_da_tarefa-início_da_tarefa+1) -> 6
B13: Ação | E13: =E10+1 -> 46152 | F13: =E13+2 -> 46154 | H13: =IF(OR(ISBLANK(início_da_tarefa),ISBLANK(término_da_tarefa)),"",término_da_tarefa-início_da_tarefa+1) -> 3
A14: A célula à direita contém o título do exemplo da Fase 2. Você pode criar uma nova fase a qualquer momento na coluna B. Este cronograma de projeto não exige fases. Para remover a fase, basta excluir a linha. Para criar um novo bloco de fases nesta linha, digite um novo Título na célula à direita. Para continuar a adicionar tarefas à fase acima, insira uma nova linha acima desta e preencha os dados da tarefa como na instrução da célula A9. Atualize os detalhes da Fase na célula à direita, com base nas instruções da célula A8. Continue navegando para baixo nas células da coluna A para saber mais. Se você ainda não adicionou as novas linhas nesta planilha, encontrará 2 exemplos adicionais de blocos de fase que foram criados nas células B20 e B26. Caso contrário, navegue pelas células da coluna A para localizar os blocos adicionais. Repita as instruções das células A8 e A9 sempre que precisar. | B14: Título Fase 2 | H14: =IF(OR(ISBLANK(início_da_tarefa),ISBLANK(término_da_tarefa)),"",término_da_tarefa-início_da_tarefa+1)
B15: Tarefa 1 | D15: 0.5 | E15: =E13+1 -> 46153 | F15: =E15+4 -> 46157 | H15: =IF(OR(ISBLANK(início_da_tarefa),ISBLANK(término_da_tarefa)),"",término_da_tarefa-início_da_tarefa+1) -> 5
